Workbook

Sheet Summary
A1: STC Pay payment failures — HyperPay-only window
A2: From Thu 03 Sep 2026 16:27 KSA (UPG + Tap switched off, HyperPay sole customer gateway) to Thu 10 Sep 2026 18:10 KSA (UPG re-enabled). Source: Salam selfcare payments (production replica), extracted Wed 16 Sep 2026 15:30 KSA.
A4: Key figures (STC Pay rail, whole window)
A5: Indicator | B5: Value | C5: Note
A6: STC Pay attempts | B6: =Daily!B13 -> 26094 | C6: Every payment where the customer chose STC Pay on the HyperPay page
A7: STC Pay successful | B7: =Daily!C13 -> 0
A8: STC Pay failed | B8: =Daily!D13 -> 26094 | C8: Declined by HyperPay before reaching STC Pay
A9: STC Pay fail rate | B9: =Daily!E13 -> 1 | C9: failed ÷ (success + failed)
A10: Distinct customers who failed | B10: 5233 | C10: Unique mobile numbers with ≥ 1 failed STC Pay attempt
A11: Customers who later paid on another rail | B11: 3981 | C11: Same mobile, a successful payment after the failure (within window + 3 days) on mada / Visa / Master / UPG
A12: Customers not recovered | B12: =B10-B11 -> 1252 | C12: No successful payment found after their STC Pay failure
A13: Amount attempted on STC Pay (SAR) | B13: =Daily!G13 -> 2405785.5 | C13: Sum of the failed attempts (includes retries of the same basket)
A14: Days in window | B14: 8 | C14: 2026-09-03 → 2026-09-10 (KSA)
A15: Average failed attempts per customer | B15: =IF(B10=0,0,B8/B10) -> 4.9864323 | C15: Customers retried repeatedly — see retry distribution
A17: Decline reasons returned by HyperPay (STC Pay, failed attempts)
A18: Result code | B18: Reason | C18: Failed attempts | D18: Distinct customers | E18: Share
A19: 800.100.156 | B19: transaction declined (format error) | C19: 26091 | D19: 5233 | E19: =IF(SUM($C$19:$C$20)=0,0,C19/SUM($C$19:$C$20)) -> 0.99988503
A20: 900.100.200 | B20: error response from connector/acquirer | C20: 3 | D20: 3 | E20: =IF(SUM($C$19:$C$20)=0,0,C20/SUM($C$19:$C$20)) -> 0.00011496896
A22: All HyperPay rails in the same window (context)
A23: Rail / brand | B23: Attempts | C23: Success | D23: Failed | E23: Pending (abandoned) | F23: Fail rate
A24: mada | B24: 43660 | C24: 32948 | D24: 10661 | E24: 0 | F24: =IF(C24+D24=0,0,D24/(C24+D24)) -> 0.24446789
A25: (initiated - no gateway answer) | B25: 35041 | C25: 0 | D25: 0 | E25: 35041 | F25: =IF(C25+D25=0,0,D25/(C25+D25)) -> 0
A26: stc_pay | B26: 26094 | C26: 0 | D26: 26094 | E26: 0 | F26: =IF(C26+D26=0,0,D26/(C26+D26)) -> 1
A27: visa | B27: 7227 | C27: 5709 | D27: 1511 | E27: 0 | F27: =IF(C27+D27=0,0,D27/(C27+D27)) -> 0.20927978
A28: master | B28: 1439 | C28: 1019 | D28: 417 | E28: 0 | F28: =IF(C28+D28=0,0,D28/(C28+D28)) -> 0.29038997
A29: credit-card | B29: 160 | C29: 51 | D29: 70 | E29: 38 | F29: =IF(C29+D29=0,0,D29/(C29+D29)) -> 0.5785124
A30: amex | B30: 30 | C30: 7 | D30: 23 | E30: 0 | F30: =IF(C30+D30=0,0,D30/(C30+D30)) -> 0.76666667
A31: "(initiated - no gateway answer)" = checkout created but the customer never completed the HyperPay page; it is not a decline and is excluded from fail rates.
A33: STC Pay failures by platform
A34: Platform | B34: Attempts | C34: Success | D34: Failed | E34: Share of STC Pay attempts
A35: android | B35: 22578 | C35: 0 | D35: 22578 | E35: =IF(SUM($B$35:$B$37)=0,0,B35/SUM($B$35:$B$37)) -> 0.86525638
A36: web | B36: 2156 | C36: 0 | D36: 2156 | E36: =IF(SUM($B$35:$B$37)=0,0,B36/SUM($B$35:$B$37)) -> 0.082624358
A37: ios | B37: 1360 | C37: 0 | D37: 1360 | E37: =IF(SUM($B$35:$B$37)=0,0,B37/SUM($B$35:$B$37)) -> 0.052119261
A39: STC Pay failures by payment purpose
A40: Purpose | B40: Attempts | C40: Success | D40: Failed | E40: Amount attempted (SAR)
A41: recharge | B41: 20697 | C41: 0 | D41: 20697 | E41: 1806063.6
A42: Checkout | B42: 2432 | C42: 0 | D42: 2432 | E42: 240445.05
A43: advanced_postpaid_payment | B43: 2189 | C43: 0 | D43: 2189 | E43: 247585.36
A44: bill | B44: 558 | C44: 0 | D44: 558 | E44: 67240.26
A45: OnboardingOrder | B45: 167 | C45: 0 | D45: 167 | E45: 43512.86
...

Sheet Daily
A1: STC Pay via HyperPay — daily failures (KSA days)
A2: Window Thu 03 Sep 2026 16:27 KSA → Thu 10 Sep 2026 18:10 KSA. STC Pay = HyperPay attempts whose payment brand / method is STC Pay. Fail rate = failed ÷ (success + failed); pending (customer never returned from the gateway page) is excluded from the rate.
A4: Day (KSA) | B4: STC Pay attempts | C4: STC Pay success | D4: STC Pay failed | E4: STC Pay fail rate | F4: Distinct customers failed | G4: Amount attempted (SAR) | H4: HyperPay other rails attempts | I4: HyperPay other rails success | J4: HyperPay other rails failed | K4: Other rails fail rate | L4: HyperPay pending (abandoned) | M4: UPG (salam) attempts | N4: UPG success | O4: UPG failed | P4: UPG fail rate
A5: 46268 | B5: 1064 | C5: 0 | D5: 1064 | E5: =IF(C5+D5=0,0,D5/(C5+D5)) -> 1 | F5: 263 | G5: 93647.35 | H5: =4584-B5 -> 3520 | I5: =1563-C5 -> 1563 | J5: =1517-D5 -> 453 | K5: =IF(I5+J5=0,0,J5/(I5+J5)) -> 0.22470238 | L5: 1500 | M5: 0 | N5: 0 | O5: 0 | P5: =IF(N5+O5=0,0,O5/(N5+O5)) -> 0
A6: 46269 | B6: 4504 | C6: 0 | D6: 4504 | E6: =IF(C6+D6=0,0,D6/(C6+D6)) -> 1 | F6: 1068 | G6: 412122.69 | H6: =19026-B6 -> 14522 | I6: =6631-C6 -> 6631 | J6: =6336-D6 -> 1832 | K6: =IF(I6+J6=0,0,J6/(I6+J6)) -> 0.2164717 | L6: 6048 | M6: 0 | N6: 0 | O6: 0 | P6: =IF(N6+O6=0,0,O6/(N6+O6)) -> 0
A7: 46270 | B7: 3993 | C7: 0 | D7: 3993 | E7: =IF(C7+D7=0,0,D7/(C7+D7)) -> 1 | F7: 949 | G7: 368387.87 | H7: =17544-B7 -> 13551 | I7: =5601-C7 -> 5601 | J7: =6700-D7 -> 2707 | K7: =IF(I7+J7=0,0,J7/(I7+J7)) -> 0.32583052 | L7: 5237 | M7: 0 | N7: 0 | O7: 0 | P7: =IF(N7+O7=0,0,O7/(N7+O7)) -> 0
A8: 46271 | B8: 4179 | C8: 0 | D8: 4179 | E8: =IF(C8+D8=0,0,D8/(C8+D8)) -> 1 | F8: 971 | G8: 389849.22 | H8: =16709-B8 -> 12530 | I8: =5807-C8 -> 5807 | J8: =5824-D8 -> 1645 | K8: =IF(I8+J8=0,0,J8/(I8+J8)) -> 0.22074611 | L8: 5069 | M8: 0 | N8: 0 | O8: 0 | P8: =IF(N8+O8=0,0,O8/(N8+O8)) -> 0
A9: 46272 | B9: 3730 | C9: 0 | D9: 3730 | E9: =IF(C9+D9=0,0,D9/(C9+D9)) -> 1 | F9: 880 | G9: 356609.48 | H9: =15173-B9 -> 11443 | I9: =5359-C9 -> 5359 | J9: =5217-D9 -> 1487 | K9: =IF(I9+J9=0,0,J9/(I9+J9)) -> 0.21720713 | L9: 4586 | M9: 0 | N9: 0 | O9: 0 | P9: =IF(N9+O9=0,0,O9/(N9+O9)) -> 0
A10: 46273 | B10: 3271 | C10: 0 | D10: 3271 | E10: =IF(C10+D10=0,0,D10/(C10+D10)) -> 1 | F10: 820 | G10: 303092.15 | H10: =14526-B10 -> 11255 | I10: =5256-C10 -> 5256 | J10: =4681-D10 -> 1410 | K10: =IF(I10+J10=0,0,J10/(I10+J10)) -> 0.21152115 | L10: 4581 | M10: 0 | N10: 0 | O10: 0 | P10: =IF(N10+O10=0,0,O10/(N10+O10)) -> 0
A11: 46274 | B11: 3501 | C11: 0 | D11: 3501 | E11: =IF(C11+D11=0,0,D11/(C11+D11)) -> 1 | F11: 839 | G11: 308579.05 | H11: =15788-B11 -> 12287 | I11: =5484-C11 -> 5484 | J11: =5500-D11 -> 1999 | K11: =IF(I11+J11=0,0,J11/(I11+J11)) -> 0.26713885 | L11: 4798 | M11: 0 | N11: 0 | O11: 0 | P11: =IF(N11+O11=0,0,O11/(N11+O11)) -> 0
A12: 46275 | B12: 1852 | C12: 0 | D12: 1852 | E12: =IF(C12+D12=0,0,D12/(C12+D12)) -> 1 | F12: 547 | G12: 173497.73 | H12: =10301-B12 -> 8449 | I12: =4033-C12 -> 4033 | J12: =3001-D12 -> 1149 | K12: =IF(I12+J12=0,0,J12/(I12+J12)) -> 0.22172906 | L12: 3260 | M12: 4035 | N12: 1683 | O12: 279 | P12: =IF(N12+O12=0,0,O12/(N12+O12)) -> 0.14220183
A13: Total | B13: =SUM(B5:B12) -> 26094 | C13: =SUM(C5:C12) -> 0 | D13: =SUM(D5:D12) -> 26094 | E13: =IF(C13+D13=0,0,D13/(C13+D13)) -> 1 | F13: =SUM(F5:F12) -> 6337 | G13: =SUM(G5:G12) -> 2405785.5 | H13: =SUM(H5:H12) -> 87557 | I13: =SUM(I5:I12) -> 39734 | J13: =SUM(J5:J12) -> 12682 | K13: =IF(I13+J13=0,0,J13/(I13+J13)) -> 0.24194902 | L13: =SUM(L5:L12) -> 35079 | M13: =SUM(M5:M12) -> 4035 | N13: =SUM(N5:N12) -> 1683 | O13: =SUM(O5:O12) -> 279 | P13: =IF(N13+O13=0,0,O13/(N13+O13)) -> 0.14220183
A14: Distinct-customer total is on the Summary sheet (a customer failing on two days is counted once there, once per day here). UPG columns show traffic only on 10 Sep after 18:10 KSA re-enable.

Sheet Hourly
A1: HyperPay hourly profile (KSA hours) — STC Pay vs all rails
A3: Hour (KSA) | B3: STC Pay attempts | C3: STC Pay failed | D3: STC Pay fail rate | E3: All HyperPay attempts | F3: All HyperPay failed | G3: All-rails fail rate
A4: 46268.792 | B4: 138 | C4: 138 | D4: =IF(B4=0,0,C4/B4) -> 1 | E4: 613 | F4: 194 | G4: =IF(E4=0,0,F4/E4) -> 0.31647635
A5: 46268.833 | B5: 204 | C5: 204 | D5: =IF(B5=0,0,C5/B5) -> 1 | E5: 973 | F5: 288 | G5: =IF(E5=0,0,F5/E5) -> 0.29599178
A6: 46268.875 | B6: 266 | C6: 266 | D6: =IF(B6=0,0,C6/B6) -> 1 | E6: 1044 | F6: 367 | G6: =IF(E6=0,0,F6/E6) -> 0.35153257
A7: 46268.917 | B7: 233 | C7: 233 | D7: =IF(B7=0,0,C7/B7) -> 1 | E7: 1014 | F7: 338 | G7: =IF(E7=0,0,F7/E7) -> 0.33333333
A8: 46268.958 | B8: 223 | C8: 223 | D8: =IF(B8=0,0,C8/B8) -> 1 | E8: 940 | F8: 330 | G8: =IF(E8=0,0,F8/E8) -> 0.35106383
A9: 46269 | B9: 232 | C9: 232 | D9: =IF(B9=0,0,C9/B9) -> 1 | E9: 1011 | F9: 342 | G9: =IF(E9=0,0,F9/E9) -> 0.33827893
A10: 46269.042 | B10: 143 | C10: 143 | D10: =IF(B10=0,0,C10/B10) -> 1 | E10: 681 | F10: 220 | G10: =IF(E10=0,0,F10/E10) -> 0.32305433
A11: 46269.083 | B11: 85 | C11: 85 | D11: =IF(B11=0,0,C11/B11) -> 1 | E11: 413 | F11: 132 | G11: =IF(E11=0,0,F11/E11) -> 0.31961259
A12: 46269.125 | B12: 72 | C12: 72 | D12: =IF(B12=0,0,C12/B12) -> 1 | E12: 287 | F12: 97 | G12: =IF(E12=0,0,F12/E12) -> 0.33797909
A13: 46269.167 | B13: 51 | C13: 51 | D13: =IF(B13=0,0,C13/B13) -> 1 | E13: 238 | F13: 94 | G13: =IF(E13=0,0,F13/E13) -> 0.39495798
A14: 46269.208 | B14: 42 | C14: 42 | D14: =IF(B14=0,0,C14/B14) -> 1 | E14: 247 | F14: 87 | G14: =IF(E14=0,0,F14/E14) -> 0.35222672
A15: 46269.25 | B15: 53 | C15: 53 | D15: =IF(B15=0,0,C15/B15) -> 1 | E15: 265 | F15: 89 | G15: =IF(E15=0,0,F15/E15) -> 0.33584906
... A169: 46275.667 | B169: 89 | C169: 89 | D169: =IF(B169=0,0,C169/B169) -> 1 | E169: 392 | F169: 124 | G169: =IF(E169=0,0,F169/E169) -> 0.31632653

Sheet Cases
A1: # | B1: Date / time (KSA) | C1: Status | D1: Amount (SAR) | E1: Platform | F1: Gateway | G1: Rail | H1: Payment method | I1: Purpose | J1: Result code | K1: Gateway reason | L1: HyperPay reference | M1: Customer mobile (masked) | N1: Payment id
A2: 1 | B2: 2026-09-03 19:27:10 | C2: fail | D2: 20 | E2: android | F2: hyperpay | G2: stc_pay | H2: credit-card | I2: recharge | J2: 800.100.156 | K2: transaction declined (format error) | L2: B4D9823F39358B1D3FC9C378F7BF7733.prod01-vm-tx02 | M2: 96••••••••69 | N2: 74fd66f6-48b3-4a59-8fe2-b5afd30e8ed0
A3: 2 | B3: 2026-09-03 19:27:26 | C3: fail | D3: 85.68 | E3: android | F3: hyperpay | G3: stc_pay | H3: credit-card | I3: recharge | J3: 800.100.156 | K3: transaction declined (format error) | L3: 4DC5DF4DC874C43E0B74E69DCB8E8DB6.prod01-vm-tx17 | M3: 96••••••••31 | N3: 9e34ccc5-7f82-489d-b9d7-335f4f2e64dd
A4: 3 | B4: 2026-09-03 19:27:59 | C4: fail | D4: 85.68 | E4: android | F4: hyperpay | G4: stc_pay | H4: credit-card | I4: recharge | J4: 800.100.156 | K4: transaction declined (format error) | L4: 6EC7B64ADF6BA54027DDE64EDC02BAAC.prod01-vm-tx04 | M4: 96••••••••31 | N4: ab9955ff-4588-4b19-af51-c22159578caf
A5: 4 | B5: 2026-09-03 19:28:00 | C5: fail | D5: 206.43 | E5: android | F5: hyperpay | G5: stc_pay | H5: credit-card | I5: recharge | J5: 800.100.156 | K5: transaction declined (format error) | L5: E2A065256B9F8C3CD53E531A81F1A518.prod01-vm-tx06 | M5: 96••••••••83 | N5: d05fd4b3-de79-4a6d-be9a-065e7866e75e
A6: 5 | B6: 2026-09-03 19:28:35 | C6: fail | D6: 206.43 | E6: android | F6: hyperpay | G6: stc_pay | H6: credit-card | I6: recharge | J6: 800.100.156 | K6: transaction declined (format error) | L6: 83E2C0DC1B0A153F37D2FF9C0F8030F1.prod01-vm-tx13 | M6: 96••••••••83 | N6: afed2200-cbfa-403c-9e9f-ffd1aeef5390
A7: 6 | B7: 2026-09-03 19:28:36 | C7: fail | D7: 20 | E7: android | F7: hyperpay | G7: stc_pay | H7: credit-card | I7: recharge | J7: 800.100.156 | K7: transaction declined (format error) | L7: 902D9F3F28A64F69759955F049327A67.prod01-vm-tx15 | M7: 96••••••••69 | N7: f2a17da0-a700-4545-a0d1-9c679b253e9e
A8: 7 | B8: 2026-09-03 19:28:36 | C8: fail | D8: 85.68 | E8: android | F8: hyperpay | G8: stc_pay | H8: credit-card | I8: recharge | J8: 800.100.156 | K8: transaction declined (format error) | L8: 5BF973A8F20D3183A4F291F0C690D626.prod01-vm-tx13 | M8: 96••••••••32 | N8: c492e33a-32e6-4e00-862e-e40462c8cc3d
A9: 8 | B9: 2026-09-03 19:28:57 | C9: fail | D9: 126.5 | E9: android | F9: hyperpay | G9: stc_pay | H9: credit-card | I9: recharge | J9: 800.100.156 | K9: transaction declined (format error) | L9: 8F03161AA0E591D54FD3FFFD4F522A6B.prod01-vm-tx15 | M9: 96••••••••12 | N9: 5ca265b3-bb5e-40bf-af2e-013fc2f7a0b3
A10: 9 | B10: 2026-09-03 19:29:22 | C10: fail | D10: 113.85 | E10: android | F10: hyperpay | G10: stc_pay | H10: credit-card | I10: advanced_postpaid_payment | J10: 800.100.156 | K10: transaction declined (format error) | L10: 43B9F4CFA90134920EE6CAFBA464837F.prod01-vm-tx05 | M10: 96••••••••46 | N10: 323f80bc-502c-4312-944b-dc3960c6ef49
A11: 10 | B11: 2026-09-03 19:29:28 | C11: fail | D11: 206.43 | E11: android | F11: hyperpay | G11: stc_pay | H11: credit-card | I11: recharge | J11: 800.100.156 | K11: transaction declined (format error) | L11: 0AD41B5B8A1FE36C6B55117D169DA7A6.prod01-vm-tx03 | M11: 96••••••••83 | N11: f9ab7093-a0ec-4334-94a2-49a069b03483
A12: 11 | B12: 2026-09-03 19:29:33 | C12: fail | D12: 113.85 | E12: android | F12: hyperpay | G12: stc_pay | H12: credit-card | I12: recharge | J12: 800.100.156 | K12: transaction declined (format error) | L12: 198292C2F9B86EE16E0037C7470578CF.prod01-vm-tx12 | M12: 96••••••••69 | N12: d861367f-7605-4556-b94e-7a66eb9b75bc
A13: 12 | B13: 2026-09-03 19:29:41 | C13: fail | D13: 85.68 | E13: android | F13: hyperpay | G13: stc_pay | H13: credit-card | I13: recharge | J13: 800.100.156 | K13: transaction declined (format error) | L13: 23FF9C02A694F079954D98169FE6A79F.prod01-vm-tx09 | M13: 96••••••••93 | N13: 5731103b-250a-4760-8c97-345c5b2e1650
... A577: 576 | B577: 2026-09-03 21:53:27 | C577: fail | D577: 102.24 | E577: android | F577: hyperpay | G577: stc_pay | H577: credit-card | I577: advanced_postpaid_payment | J577: 800.100.156 | K577: transaction declined (format error) | L577: 3BAF87153A00BBCEA42E2CEEB9800C8E.prod01-vm-tx01 | M577: 96••••••••12 | N577: 343652e2-e916-4834-989e-9afc7ea15654
A578: 577 | B578: 2026-09-03 21:53:44 | C578: fail | D578: 113.85 | E578: android | F578: hyperpay | G578: stc_pay | H578: credit-card | I578: OnboardingOrder | J578: 800.100.156 | K578: transaction declined (format error) | L578: E5A27005AD8BB1026484FA02BF1B3AE9.prod01-vm-tx06 | N578: 5fc7522c-b65f-4414-a338-f4f1d557212b
A579: 578 | B579: 2026-09-03 21:53:47 | C579: fail | D579: 85.68 | E579: web | F579: hyperpay | G579: stc_pay | H579: credit-card | I579: Checkout | J579: 800.100.156 | K579: transaction declined (format error) | L579: 8549E6259F608CD74953D529A52EDB28.prod01-vm-tx16 | M579: 96••••••••06 | N579: bbbadbbe-8b53-4b24-824b-dc15a3f204b8
A580: 579 | B580: 2026-09-03 21:53:47 | C580: fail | D580: 85.68 | E580: android | F580: hyperpay | G580: stc_pay | H580: credit-card | I580: recharge | J580: 800.100.156 | K580: transaction declined (format error) | L580: CEA869F670E4C4571E202BCB0D79FD96.prod01-vm-tx10 | M580: 96••••••••47 | N580: 5d9545e1-26c5-4a19-a9e7-a6d867e89424
A581: 580 | B581: 2026-09-03 21:53:48 | C581: fail | D581: 102.24 | E581: android | F581: hyperpay | G581: stc_pay | H581: credit-card | I581: advanced_postpaid_payment | J581: 800.100.156 | K581: transaction declined (format error) | L581: 54BF87D6F55344C7482418D3DAF9CB5B.prod01-vm-tx13 | M581: 96••••••••12 | N581: df3c1d47-a8f6-4847-9665-2d209b97aedf
A582: 581 | B582: 2026-09-03 21:54:20 | C582: fail | D582: 20 | E582: android | F582: hyperpay | G582: stc_pay | H582: credit-card | I582: recharge | J582: 800.100.156 | K582: transaction declined (format error) | L582: 65F0A3AFD78DD81B0263D138BB1D348D.prod01-vm-tx13 | M582: 96••••••••44 | N582: 94fd0322-0cc8-4b67-ba7a-3e543a1a5ce0
A583: 582 | B583: 2026-09-03 21:54:21 | C583: fail | D583: 85.68 | E583: android | F583: hyperpay | G583: stc_pay | H583: credit-card | I583: recharge | J583: 800.100.156 | K583: transaction declined (format error) | L583: BF75E3F9386BFC3D33E95B76FF825AAD.prod01-vm-tx10 | M583: 96••••••••32 | N583: 5ccb41c8-b12f-4903-b49f-487023e6b2c3
A584: 583 | B584: 2026-09-03 21:54:25 | C584: fail | D584: 113.85 | E584: android | F584: hyperpay | G584: stc_pay | H584: credit-card | I584: Checkout | J584: 800.100.156 | K584: transaction declined (format error) | L584: B0195F4D7D84BB90294EDCF576897E03.prod01-vm-tx04 | M584: 96••••••••30 | N584: a02ce176-6c1f-4d0b-bb6d-bc6b28a009db
A585: 584 | B585: 2026-09-03 21:54:47 | C585: fail | D585: 85.68 | E585: android | F585: hyperpay | G585: stc_pay | H585: credit-card | I585: recharge | J585: 800.100.156 | K585: transaction declined (format error) | L585: 36C97666CA302AEACC1225D4699EB3BA.prod01-vm-tx08 | M585: 96••••••••06 | N585: f86076ec-d3fe-4389-b66f-b6b1ada594ba
A586: 585 | B586: 2026-09-03 21:54:51 | C586: fail | D586: 85.68 | E586: android | F586: hyperpay | G586: stc_pay | H586: credit-card | I586: recharge | J586: 800.100.156 | K586: transaction declined (format error) | L586: 217B5E68D67A6A6B46F1A0E92951D48C.prod01-vm-tx12 | M586: 96••••••••32 | N586: f57f2dc2-6b94-44b9-b0a5-cf64d545bf37
A587: 586 | B587: 2026-09-03 21:54:52 | C587: fail | D587: 30 | E587: android | F587: hyperpay | G587: stc_pay | H587: credit-card | I587: recharge | J587: 800.100.156 | K587: transaction declined (format error) | L587: 3F7B9B8769E67D90C2FFF5A1CDC21626.prod01-vm-tx14 | M587: 96••••••••44 | N587: c1af3009-b425-4603-b519-299db6970a37
A588: 587 | B588: 2026-09-03 21:55:02 | C588: fail | D588: 153.13 | E588: android | F588: hyperpay | G588: stc_pay | H588: credit-card | I588: advanced_postpaid_payment | J588: 800.100.156 | K588: transaction declined (format error) | L588: B8C7F11497B6BC87F8BE7139B6DC102B.prod01-vm-tx04 | M588: 96••••••••36 | N588: 11eff15b-a92e-450f-8d74-f6669e64ffcc
A589: 588 | B589: 2026-09-03 21:55:18 | C589: fail | D589: 85.68 | E589: android | F589: hyperpay | G589: stc_pay | H589: credit-card | I589: recharge | J589: 800.100.156 | K589: transaction declined (format error) | L589: F29E5D62AE9837278719982A424E49D1.prod01-vm-tx04 | M589: 96••••••••72 | N589: f23bd0c1-b701-4b39-9368-665cd073a551
A590: 589 | B590: 2026-09-03 21:55:20 | C590: fail | D590: 20 | E590: android | F590: hyperpay | G590: stc_pay | H590: credit-card | I590: recharge | J590: 800.100.156 | K590: transaction declined (format error) | L590: 640668183350AE8BEDA92C2C896944BB.prod01-vm-tx09 | M590: 96••••••••44 | N590: 49b0e4a0-9a6c-4d4b-a621-a063ec94c7a5
... A713: 712 | B713: 2026-09-03 22:32:09 | C713: fail | D713: 228.85 | E713: android | F713: hyperpay | G713: stc_pay | H713: credit-card | I713: Checkout | J713: 800.100.156 | K713: transaction declined (format error) | L713: EDAC1FAD1E0021C6BB9C586CFA928596.prod01-vm-tx04 | M713: 96••••••••82 | N713: 966fe3bf-32c2-4711-afb8-517349573964
A714: 713 | B714: 2026-09-03 22:32:28 | C714: fail | D714: 85.68 | E714: web | F714: hyperpay | G714: stc_pay | H714: credit-card | I714: OnboardingOrder | J714: 800.100.156 | K714: transaction declined (format error) | L714: 92D34994C668AD72139AC3984C322E2A.prod01-vm-tx11 | N714: 956539c7-f356-4f4f-b81b-290d95bcb782
A715: 714 | B715: 2026-09-03 22:32:55 | C715: fail | D715: 228.85 | E715: android | F715: hyperpay | G715: stc_pay | H715: credit-card | I715: Checkout | J715: 800.100.156 | K715: transaction declined (format error) | L715: 1EF3BA578AFBA78A299A175A6A5A22A3.prod01-vm-tx17 | M715: 96••••••••82 | N715: 9188d6fc-5e0d-4c55-b1bb-48a88406e7bf
A716: 715 | B716: 2026-09-03 22:33:25 | C716: fail | D716: 85.68 | E716: android | F716: hyperpay | G716: stc_pay | H716: credit-card | I716: recharge | J716: 800.100.156 | K716: transaction declined (format error) | L716: 64BFFDBBCAFE6130C6F3F8ACBB21D41C.prod01-vm-tx13 | M716: 96••••••••16 | N716: 27f36749-a7ba-44ce-8306-a1ef23fb4efa
A717: 716 | B717: 2026-09-03 22:33:50 | C717: fail | D717: 114.48 | E717: android | F717: hyperpay | G717: stc_pay | H717: credit-card | I717: advanced_postpaid_payment | J717: 800.100.156 | K717: transaction declined (format error) | L717: CCCA1803AE4ABB773BF431F9E6FDD9FE.prod01-vm-tx01 | M717: 96••••••••76 | N717: 1e164305-b155-43b4-a395-73f0e5fe0d51
A718: 717 | B718: 2026-09-03 22:33:53 | C718: fail | D718: 85.68 | E718: android | F718: hyperpay | G718: stc_pay | H718: credit-card | I718: recharge | J718: 800.100.156 | K718: transaction declined (format error) | L718: DA704B7CA373698CBBF8AC7F93C64522.prod01-vm-tx13 | M718: 96••••••••16 | N718: 22002db3-0d74-41f7-8d3e-c0b035375a2e
A719: 718 | B719: 2026-09-03 22:34:07 | C719: fail | D719: 85.68 | E719: android | F719: hyperpay | G719: stc_pay | H719: credit-card | I719: Checkout | J719: 800.100.156 | K719: transaction declined (format error) | L719: 39D918D9F1F99CA4629F86AF1FE8C249.prod01-vm-tx09 | M719: 96••••••••70 | N719: 7df733e7-8fcf-4a82-93d3-217d4c2a31ea
A720: 719 | B720: 2026-09-03 22:34:10 | C720: fail | D720: 114.48 | E720: android | F720: hyperpay | G720: stc_pay | H720: credit-card | I720: advanced_postpaid_payment | J720: 800.100.156 | K720: transaction declined (format error) | L720: 0A796511398F463A37FECEEF59CA6A23.prod01-vm-tx16 | M720: 96••••••••76 | N720: 26ec70c7-e3c5-4cde-8754-0cdad79db686
A721: 720 | B721: 2026-09-03 22:34:23 | C721: fail | D721: 104.22 | E721: android | F721: hyperpay | G721: stc_pay | H721: credit-card | I721: advanced_postpaid_payment | J721: 800.100.156 | K721: transaction declined (format error) | L721: 5A4686A748487AA87813A39A16CD0548.prod01-vm-tx11 | M721: 96••••••••81 | N721: a1140299-82b7-47c1-b5a3-dd4b6c3ea2a7
A722: 721 | B722: 2026-09-03 22:34:35 | C722: fail | D722: 228.85 | E722: android | F722: hyperpay | G722: stc_pay | H722: credit-card | I722: Checkout | J722: 800.100.156 | K722: transaction declined (format error) | L722: 8772E9963EBFC33FA5E7738EC3808979.prod01-vm-tx16 | M722: 96••••••••82 | N722: 256233bd-9f74-47c8-94d1-558cbfd38b55
A723: 722 | B723: 2026-09-03 22:34:40 | C723: fail | D723: 85.68 | E723: android | F723: hyperpay | G723: stc_pay | H723: credit-card | I723: Checkout | J723: 800.100.156 | K723: transaction declined (format error) | L723: A143AE2D552CAB453BC6B9134D19AC4A.prod01-vm-tx17 | M723: 96••••••••70 | N723: 6366767e-24c8-4503-966c-7481be81666e
A724: 723 | B724: 2026-09-03 22:34:40 | C724: fail | D724: 85.68 | E724: android | F724: hyperpay | G724: stc_pay | H724: credit-card | I724: recharge | J724: 800.100.156 | K724: transaction declined (format error) | L724: F64C023450E1659ABBD9479A68A8B98F.prod01-vm-tx01 | M724: 96••••••••30 | N724: 1e156788-03bb-4e5b-ba7a-7a08f1aee687
A725: 724 | B725: 2026-09-03 22:34:47 | C725: fail | D725: 104.22 | E725: android | F725: hyperpay | G725: stc_pay | H725: credit-card | I725: advanced_postpaid_payment | J725: 800.100.156 | K725: transaction declined (format error) | L725: 9D51FE66F1C91B9B302E03F35EAF8DF0.prod01-vm-tx05 | M725: 96••••••••81 | N725: ba28b853-1513-462c-81b8-b7089d6f1ac3
...

Sheet Baseline
A1: Daily volumes by gateway, 7 days before the cutover (KSA days)
A3: Day (KSA) | B3: Gateway | C3: Attempts | D3: Success | E3: Failed | F3: Fail rate
A4: 46261 | B4: apollo | C4: 228 | D4: 208 | E4: 0 | F4: =IF(D4+E4=0,0,E4/(D4+E4)) -> 0
A5: 46261 | B5: hyperpay | C5: 6 | D5: 2 | E5: 0 | F5: =IF(D5+E5=0,0,E5/(D5+E5)) -> 0
A6: 46261 | B6: salam | C6: 4691 | D6: 2324 | E6: 470 | F6: =IF(D6+E6=0,0,E6/(D6+E6)) -> 0.16821761
A7: 46262 | B7: apollo | C7: 560 | D7: 525 | E7: 0 | F7: =IF(D7+E7=0,0,E7/(D7+E7)) -> 0
A8: 46262 | B8: hyperpay | C8: 14 | D8: 7 | E8: 0 | F8: =IF(D8+E8=0,0,E8/(D8+E8)) -> 0
A9: 46262 | B9: salam | C9: 20274 | D9: 11655 | E9: 1894 | F9: =IF(D9+E9=0,0,E9/(D9+E9)) -> 0.13978891
A10: 46263 | B10: apollo | C10: 626 | D10: 575 | E10: 0 | F10: =IF(D10+E10=0,0,E10/(D10+E10)) -> 0
A11: 46263 | B11: hyperpay | C11: 5 | D11: 4 | E11: 1 | F11: =IF(D11+E11=0,0,E11/(D11+E11)) -> 0.2
A12: 46263 | B12: salam | C12: 15594 | D12: 8689 | E12: 1540 | F12: =IF(D12+E12=0,0,E12/(D12+E12)) -> 0.15055235
A13: 46264 | B13: apollo | C13: 536 | D13: 503 | E13: 0 | F13: =IF(D13+E13=0,0,E13/(D13+E13)) -> 0
A14: 46264 | B14: hyperpay | C14: 3 | D14: 3 | E14: 0 | F14: =IF(D14+E14=0,0,E14/(D14+E14)) -> 0
A15: 46264 | B15: salam | C15: 16731 | D15: 9160 | E15: 1792 | F15: =IF(D15+E15=0,0,E15/(D15+E15)) -> 0.16362308
... A27: 46268 | B27: salam | C27: 9562 | D27: 4339 | E27: 684 | F27: =IF(D27+E27=0,0,E27/(D27+E27)) -> 0.1361736

Sheet Method
A1: Method & definitions
A3: Source | B3: Salam selfcare `payments` table, production replica (same rows as production; read-only extract by the Operations Console on ruh-salam-site03).
A4: Window | B4: Thu 03 Sep 2026 16:27 KSA → Thu 10 Sep 2026 18:10 KSA. Start = gateway registry cutover (UPG + Tap disabled, HyperPay only). End = gateway registry "UPG re-enabled" timestamp (gateway registry: UPG re-enabled by y.yahmed.sns@salam.sa).
A5: STC Pay attempt | B5: A HyperPay payment whose gateway response paymentBrand, card_type or payment_method contains "stc". Identified per row, not by customer.
A6: Status | B6: success = gateway confirmed; fail = gateway declined; pending = checkout created but customer never completed the gateway page (abandoned). Fail rate = fail ÷ (success + fail).
A7: Distinct customers | B7: Unique customer mobile numbers with at least one failed STC Pay attempt in the window.
A8: Later paid on another rail | B8: A customer counted above who has a successful payment on any non-STC Pay rail (mada / Visa / Master / UPG) after the failed attempt and before window end + 3 days.
A9: Amount attempted | B9: Sum of the amount field over failed STC Pay rows. Retries of the same basket are counted each time, so it is exposure, not lost revenue.
A10: Result code 800.100.156 | B10: HyperPay: "transaction declined (format error)" — the request rejected by the acquirer/connector configuration before any customer authentication; no STC Pay OTP was ever shown.
A11: Masking | B11: Customer mobiles are masked (first two + last two digits). Full identifiers can be provided from the console on request.
A12: Times | B12: All dates and times are KSA (UTC+3).
